Workbook

Sheet 00_Tong_quan
A1: DIGIWIN | SEMICONDUCTOR PAID
A3: Đơn vị tiền: VNĐ. Theo dõi đề xuất ngân sách, triển khai và đánh giá. Mục tiêu: xây dựng nhận thức về chuyên môn vận hành ngành bán dẫn trong đúng nhóm doanh nghiệp và vai trò.
A5: KHUNG CƠ BẢN ĐỀ XUẤT / NGÀY | E5: KHUNG CẤP 2 / DUYỆT RIÊNG | I5: THỰC CHI QUẢNG CÁO
A6: ='01_Thiet_lap'!$D$7 | E6: ='01_Thiet_lap'!$D$12 | I6: =IF(COUNT('03_Chi_tieu'!$I$7:$I$96)=0,"Chưa ghi nhận",SUM('03_Chi_tieu'!$I$7:$I$96))
A9: NGÀY HỢP LỆ ĐÃ GHI NHẬN | E9: DỰ PHÒNG CÒN GIỮ | I9: DÒNG CHI CẦN RÀ SOÁT
A10: =SUM('03_Chi_tieu'!$S$7:$S$96) | E10: =IF(SUM('03_Chi_tieu'!$S$7:$S$96)=0,"Chưa ghi nhận",IF(COUNT('03_Chi_tieu'!$K$7:$K$96)<SUM('03_Chi_tieu'!$S$7:$S$96),"Chưa đầy đủ",SUM('03_Chi_tieu'!$K$7:$K$96))) | I10: =COUNTIF('03_Chi_tieu'!$P$7:$P$96,"?*")-COUNTIF('03_Chi_tieu'!$P$7:$P$96,"Đã ghi nhận")
A13: ="Phạm vi thuế/phí: "&'01_Thiet_lap'!$D$27&" | Bắt đầu: "&IF(ISNUMBER('01_Thiet_lap'!$D$25),TEXT('01_Thiet_lap'!$D$25,"dd/mm/yyyy"),'01_Thiet_lap'!$D$25)&" | Kết thúc: "&IF(ISNUMBER('01_Thiet_lap'!$D$26),TEXT('01_Thiet_lap'!$D$26,"dd/mm/yyyy"),'01_Thiet_lap'!$D$26)
A16: Mã | B16: Giai đoạn | E16: Phê duyệt | G16: Hợp lệ | H16: Mốc ngày | I16: Thực chi quảng cáo
A17: ='02_Lo_trinh'!A7 | B17: ='02_Lo_trinh'!B7 | E17: ='02_Lo_trinh'!J7 | G17: ='02_Lo_trinh'!K7 | H17: ='02_Lo_trinh'!C7 | I17: =IF(ISNUMBER('02_Lo_trinh'!L7),'02_Lo_trinh'!L7,"Chưa ghi nhận")
A18: ='02_Lo_trinh'!A8 | B18: ='02_Lo_trinh'!B8 | E18: ='02_Lo_trinh'!J8 | G18: ='02_Lo_trinh'!K8 | H18: ='02_Lo_trinh'!C8 | I18: =IF(ISNUMBER('02_Lo_trinh'!L8),'02_Lo_trinh'!L8,"Chưa ghi nhận")
A19: ='02_Lo_trinh'!A9 | B19: ='02_Lo_trinh'!B9 | E19: ='02_Lo_trinh'!J9 | G19: ='02_Lo_trinh'!K9 | H19: ='02_Lo_trinh'!C9 | I19: =IF(ISNUMBER('02_Lo_trinh'!L9),'02_Lo_trinh'!L9,"Chưa ghi nhận")
A20: ='02_Lo_trinh'!A10 | B20: ='02_Lo_trinh'!B10 | E20: ='02_Lo_trinh'!J10 | G20: ='02_Lo_trinh'!K10 | H20: ='02_Lo_trinh'!C10 | I20: =IF(ISNUMBER('02_Lo_trinh'!L10),'02_Lo_trinh'!L10,"Chưa ghi nhận")
A21: ='02_Lo_trinh'!A11 | B21: ='02_Lo_trinh'!B11 | E21: ='02_Lo_trinh'!J11 | G21: ='02_Lo_trinh'!K11 | H21: ='02_Lo_trinh'!C11 | I21: =IF(ISNUMBER('02_Lo_trinh'!L11),'02_Lo_trinh'!L11,"Chưa ghi nhận")
A23: ="Khung tham chiếu đến hết cấp 1 • "&SUM('02_Lo_trinh'!$C$7:$C$10)&" ngày hợp lệ (có điều kiện)" | I23: =SUM('02_Lo_trinh'!$G$7:$G$10)
A26: Phân bổ khởi động | E26: Dự kiến/ngày | G26: Tỷ trọng | I26: Thực chi đã ghi nhận
A27: LinkedIn | E27: ='01_Thiet_lap'!$D$8 | G27: =IF('01_Thiet_lap'!$D$7>0,E27/'01_Thiet_lap'!$D$7,"") | I27: =IF(COUNT('03_Chi_tieu'!$E$7:$E$96)=0,"Chưa ghi nhận",SUM('03_Chi_tieu'!$E$7:$E$96))
A28: Google Search | E28: ='01_Thiet_lap'!$D$9 | G28: =IF('01_Thiet_lap'!$D$7>0,E28/'01_Thiet_lap'!$D$7,"") | I28: =IF(COUNT('03_Chi_tieu'!$F$7:$F$96)=0,"Chưa ghi nhận",SUM('03_Chi_tieu'!$F$7:$F$96))
A29: Tiếp thị lại | E29: =0 | G29: =IF('01_Thiet_lap'!$D$7>0,E29/'01_Thiet_lap'!$D$7,"") | I29: =IF(COUNT('03_Chi_tieu'!$G$7:$G$96)=0,"Chưa ghi nhận",SUM('03_Chi_tieu'!$G$7:$G$96))
A30: Thử nghiệm khác | E30: =0 | G30: =IF('01_Thiet_lap'!$D$7>0,E30/'01_Thiet_lap'!$D$7,"") | I30: =IF(COUNT('03_Chi_tieu'!$H$7:$H$96)=0,"Chưa ghi nhận",SUM('03_Chi_tieu'!$H$7:$H$96))
A31: Dự phòng (đã nằm trong chi phí kênh) | E31: ='01_Thiet_lap'!$D$10 | G31: =IF('01_Thiet_lap'!$D$7>0,E31/'01_Thiet_lap'!$D$7,"") | I31: =IF(COUNT('03_Chi_tieu'!$J$7:$J$96)=0,"Chưa ghi nhận",SUM('03_Chi_tieu'!$J$7:$J$96))
A33: Dự phòng không phải khoản chi cộng thêm: phần đã dùng nằm trong thực chi của từng kênh. Dự phòng còn giữ chỉ tổng hợp theo ngày hợp lệ có dữ liệu đầy đủ, không mặc định được chuyển sang kỳ sau. Mọi số liệu thực tế hiện để trống, chờ cập nhật.
A37: CÁCH SỬ DỤNG BẢNG THEO DÕI
A38: 01_Thiet_lap | D38: Xác nhận phạm vi ngân sách, ngày chạy, mốc đánh giá và định nghĩa chỉ số. Các phương án cấp 1 được đặt ở cuối sheet.
A39: 02_Lo_trinh | D39: Cập nhật ngày và phê duyệt từng giai đoạn. Theo dõi ngày hợp lệ, thực chi và phần khung còn lại.
A40: 03_Chi_tieu | D40: Mỗi ngày một dòng. Nhập đủ bốn khoản chi; nhập dự phòng sử dụng và thuế/phí riêng. Nhập 0 nếu không phát sinh.
A41: 04_Danh_gia | D41: Điền số liệu và bằng chứng theo mã kỳ KY01–KY12. Kết quả chỉ là tham chiếu cho đánh giá.
A42: 05_Bao_cao_tuan | D42: Chốt khoảng ngày theo thực tế; cập nhật nhóm tiếp cận, mức quan tâm, nội dung rút ra và đề xuất tiếp theo.
A43: 06_Kiem_tra | D43: Xác nhận điều kiện triển khai, đầu mối phụ trách và hồ sơ. Ngày chưa thống nhất tiếp tục để placeholder.
A45: Ký hiệu: ô vàng là nơi nhập/cập nhật; ô xám là công thức hoặc nội dung tham chiếu. Thay [Chưa chốt] bằng ngày Excel thực (dd/mm/yyyy), không nhập ngày dưới dạng ghi chú. Nhật ký có sẵn 90 dòng, báo cáo và đánh giá có 12 kỳ.
A49: Lưu ý về lộ trình: bản nháp nêu mở rộng cấp 1 theo chu kỳ 7 ngày và yêu cầu hai chu kỳ trước khi xét cấp 2; mẫu tách G3.1/G3.2 để thống nhất hai nội dung. Mức 1.250.000 VNĐ/ngày, lịch chạy và tổng chi theo các giai đoạn đều chưa mặc định được duyệt. Nguồn số liệu đề xuất: nội dung được cung cấp trong cuộc trao đổi; không bổ sung chuẩn thị trường hoặc kết quả giả định.

Sheet 01_Thiet_lap
A1: THIẾT LẬP NGÂN SÁCH & MỐC THAM CHIẾU
A3: Nguồn: bản nháp đề xuất được cung cấp trong cuộc trao đổi. Các giá trị là đề xuất nội bộ, chưa mặc định được phê duyệt.
A6: Mã | B6: Thông số | D6: Giá trị / trạng thái | F6: Cơ sở và cách sử dụng
A7: NS01 | B7: Khung quảng cáo cơ bản/ngày | D7: 1000000 | F7: Bản nháp: 1.000.000 VNĐ/ngày chạy hợp lệ; là mốc quản trị bình quân.
A8: NS02 | B8: LinkedIn cơ sở/ngày | D8: 600000 | F8: Bản nháp: phân bổ khởi động cho LinkedIn.
A9: NS03 | B9: Google Search cơ sở/ngày | D9: 250000 | F9: Bản nháp: phân bổ khởi động cho Google Search.
A10: NS04 | B10: Dự phòng trong khung cơ bản/ngày | D10: 150000 | F10: Bản nháp: giữ lại khi chưa có thử nghiệm hoặc phương án đủ căn cứ.
A11: NS05 | B11: Tổng phân bổ cơ sở/ngày | D11: =SUM(D8:D9) | F11: Tự tính từ LinkedIn và Google Search; chưa bao gồm dự phòng.
A12: NS06 | B12: Khung cấp 2 đề xuất/ngày | D12: 1250000 | F12: Bản nháp: chỉ triển khai sau khi được phê duyệt riêng.
A13: TG01 | B13: Số ngày giai đoạn thử nghiệm | D13: 7 | F13: Bản nháp: 7 ngày chạy hợp lệ.
A14: TG02 | B14: Số ngày giai đoạn xác nhận | D14: 14 | F14: Bản nháp: 14 ngày chạy hợp lệ.
A15: TG03 | B15: Số ngày mỗi chu kỳ cấp 1 | D15: 7 | F15: Bản nháp: mỗi chu kỳ mở rộng cấp 1 kéo dài 7 ngày hợp lệ.
A16: TG04 | B16: Số chu kỳ cấp 1 trước khi xét cấp 2 | D16: 2 | F16: Bản nháp yêu cầu hai chu kỳ 7 ngày. Mẫu đã tách hai chu kỳ; điều chỉnh số chu kỳ cần cập nhật cấu trúc lộ trình.
A17: TG05 | B17: Số ngày đầu của cấp 2 | D17: 7 | F17: Bản nháp: 7 ngày đầu sau khi được phê duyệt.
A18: DG01 | B18: Tỷ lệ nhấp Search đúng chủ đề | D18: 0.7 | F18: Bản nháp: tối thiểu 7/10 lượt nhấp quan sát được; mốc tham chiếu ban đầu.
A19: DG02 | B19: Duy trì mức quan tâm tối thiểu | D19: 0.8 | F19: Bản nháp: tối thiểu 80% so với mốc ban đầu; dùng cùng một chỉ số.
A20: DG03 | B20: Mức cải thiện tham chiếu | D20: 0.2 | F20: Bản nháp: cải thiện tối thiểu 20%; chỉ số cần được thống nhất trước.
A21: DG04 | B21: Mức giảm chi phí tham chiếu | D21: 0.15 | F21: Bản nháp: chi phí thấp hơn tối thiểu 15%, kèm chất lượng tương đương.
A22: DG05 | B22: Mức suy giảm tối đa khi xét cấp 2 | D22: 0.1 | F22: Bản nháp: mức suy giảm không vượt quá 10%; cần hai chu kỳ cấp 1.
A23: DG06 | B23: Số nhấp để đối chiếu mốc 7/10 | D23: 10 | F23: Quy ước theo dõi từ mốc 7/10; không thay thế đánh giá độ tin cậy của mẫu.
A24: NS07 | B24: Dự phòng cấp 2/ngày | D24: [Chưa chốt] | F24: Chưa có phân bổ chi tiết trong bản nháp. Cập nhật khi trình duyệt cấp 2.
A25: TG06 | B25: Ngày bắt đầu chiến dịch | D25: [Chưa chốt] | F25: Thay placeholder bằng ngày thực tế sau khi được thống nhất.
A26: TG07 | B26: Ngày kết thúc chiến dịch | D26: [Chưa chốt] | F26: Không tự suy ra ngày kết thúc từ số ngày lịch.
A27: PD01 | B27: Phạm vi thuế và phí | D27: Chưa xác nhận | F27: Cần tách thuế/phí trước khi áp dụng nếu khung được duyệt đã bao gồm các khoản này.
A28: DL01 | B28: Chỉ số mức độ quan tâm | D28: [Chưa thống nhất] | F28: Ghi tên chỉ số và cách đo; giữ nhất quán giữa mốc ban đầu và kỳ hiện tại.
A29: DL02 | B29: Chỉ số đánh giá cải thiện | D29: [Chưa thống nhất] | F29: Chọn chỉ số mà giá trị tăng thể hiện cải thiện; ghi rõ đơn vị và nguồn.
A30: DL03 | B30: Đơn vị chi phí dùng để đối chiếu | D30: [Chưa thống nhất] | F30: Thống nhất cùng một đơn vị chi phí và điều kiện chất lượng.
A31: PD02 | B31: Phạm vi điều chỉnh được duyệt | D31: [Chưa thống nhất] | F31: Ghi thẩm quyền điều chỉnh giữa các kênh và sử dụng dự phòng.
A32: DL04 | B32: Nguồn dữ liệu và ngày hợp lệ | D32: [Chưa thống nhất] | F32: Ghi nguồn đối chiếu và điều kiện xác nhận ngày chạy, gồm trạng thái từng kênh.
A33: NS08 | B33: Dự phòng còn lại sau ưu tiên cấp 1 | D33: 50000 | F33: Bản nháp: các phương án cấp 1 dùng thêm 100.000 VNĐ, giữ lại 50.000 VNĐ.
A35: Ô vàng: nhập/cập nhật sau khi thống nhất. Ô xám: công thức. Đơn vị tiền: VNĐ. Các mốc tỷ lệ là tham chiếu vận hành, không tự động quyết định tăng ngân sách.
A38: Phương án phân bổ/ngày | C38: LinkedIn | D38: Google Search | E38: Tiếp thị lại | F38: Dự phòng còn giữ | G38: Tổng khung
A39: Khởi động | C39: =$D$8 | D39: =$D$9 | E39: =0 | F39: =$D$10 | G39: =SUM(C39:F39)
A40: Ưu tiên LinkedIn | C40: =$D$8+$D$10-$D$33 | D40: =$D$9 | E40: =0 | F40: =$D$33 | G40: =SUM(C40:F40)
A41: Ưu tiên Search | C41: =$D$8 | D41: =$D$9+$D$10-$D$33 | E41: =0 | F41: =$D$33 | G41: =SUM(C41:F41)
A42: Ưu tiên tiếp thị lại | C42: =$D$8 | D42: =$D$9 | E42: =$D$10-$D$33 | F42: =$D$33 | G42: =SUM(C42:F42)
A43: Cấp 2 — chờ phân bổ | C43: [Chưa chốt] | D43: [Chưa chốt] | E43: [Chưa chốt] | F43: [Chưa chốt] | G43: =$D$12
A45: Dự phòng sử dụng trong nhật ký chi là một phần của chi phí kênh, không cộng thêm lần nữa. Các phương án cấp 1 giữ tổng 1.000.000 VNĐ/ngày. Phương án cấp 2 cần chốt phân bổ và phê duyệt riêng.

Sheet 02_Lo_trinh
A1: LỘ TRÌNH TRIỂN KHAI & PHÊ DUYỆT
A3: Ngày bắt đầu/kết thúc để [Chưa chốt]. Hai chu kỳ cấp 1 được tách riêng; đủ số ngày chưa đồng nghĩa với đủ điều kiện mở rộng.
A6: Mã | B6: Giai đoạn | C6: Ngày tham chiếu | D6: Ngày bắt đầu | E6: Ngày kết thúc | F6: Khung đề xuất/ngày | G6: Khung tối đa/chu kỳ | H6: Trong đó: cơ sở | I6: Trong đó: dự phòng | J6: Phê duyệt | K6: Ngày hợp lệ đã ghi nhận | L6: Thực chi quảng cáo | M6: Phần khung chưa dùng | N6: Trọng tâm / bước tiếp theo
A7: G1 | B7: 1. Thử nghiệm | C7: ='01_Thiet_lap'!$D$13 | D7: [Chưa chốt] | E7: [Chưa chốt] | F7: ='01_Thiet_lap'!$D$7 | G7: =C7*F7 | H7: =C7*'01_Thiet_lap'!$D$11 | I7: =C7*'01_Thiet_lap'!$D$10 | J7: Chờ xem xét | K7: =SUMIF('03_Chi_tieu'!$B$7:$B$96,A7,'03_Chi_tieu'!$S$7:$S$96) | L7: =IF(COUNTIFS('03_Chi_tieu'!$B$7:$B$96,A7,'03_Chi_tieu'!$I$7:$I$96,">0")=0,"",SUMIF('03_Chi_tieu'!$B$7:$B$96,A7,'03_Chi_tieu'!$I$7:$I$96)) | M7: =IF(ISNUMBER(L7),G7-L7,"") | N7: Đối chiếu đúng tệp, nhu cầu tìm kiếm và hệ thống đo lường.
A8: G2 | B8: 2. Xác nhận | C8: ='01_Thiet_lap'!$D$14 | D8: [Chưa chốt] | E8: [Chưa chốt] | F8: ='01_Thiet_lap'!$D$7 | G8: =C8*F8 | H8: =C8*'01_Thiet_lap'!$D$11 | I8: =C8*'01_Thiet_lap'!$D$10 | J8: Chờ xem xét | K8: =SUMIF('03_Chi_tieu'!$B$7:$B$96,A8,'03_Chi_tieu'!$S$7:$S$96) | L8: =IF(COUNTIFS('03_Chi_tieu'!$B$7:$B$96,A8,'03_Chi_tieu'!$I$7:$I$96,">0")=0,"",SUMIF('03_Chi_tieu'!$B$7:$B$96,A8,'03_Chi_tieu'!$I$7:$I$96)) | M8: =IF(ISNUMBER(L8),G8-L8,"") | N8: Theo dõi thông điệp/nhóm có tín hiệu tốt và khả năng duy trì.
A9: G3.1 | B9: 3. Cấp 1 — chu kỳ 1 | C9: ='01_Thiet_lap'!$D$15 | D9: [Chưa chốt] | E9: [Chưa chốt] | F9: ='01_Thiet_lap'!$D$7 | G9: =C9*F9 | H9: =C9*'01_Thiet_lap'!$D$11 | I9: =C9*'01_Thiet_lap'!$D$10 | J9: Chờ xem xét | K9: =SUMIF('03_Chi_tieu'!$B$7:$B$96,A9,'03_Chi_tieu'!$S$7:$S$96) | L9: =IF(COUNTIFS('03_Chi_tieu'!$B$7:$B$96,A9,'03_Chi_tieu'!$I$7:$I$96,">0")=0,"",SUMIF('03_Chi_tieu'!$B$7:$B$96,A9,'03_Chi_tieu'!$I$7:$I$96)) | M9: =IF(ISNUMBER(L9),G9-L9,"") | N9: Điều chỉnh dự phòng trong tổng khung 1.000.000 VNĐ/ngày.
A10: G3.2 | B10: 3. Cấp 1 — chu kỳ 2 | C10: ='01_Thiet_lap'!$D$15 | D10: [Chưa chốt] | E10: [Chưa chốt] | F10: ='01_Thiet_lap'!$D$7 | G10: =C10*F10 | H10: =C10*'01_Thiet_lap'!$D$11 | I10: =C10*'01_Thiet_lap'!$D$10 | J10: Chờ xem xét | K10: =SUMIF('03_Chi_tieu'!$B$7:$B$96,A10,'03_Chi_tieu'!$S$7:$S$96) | L10: =IF(COUNTIFS('03_Chi_tieu'!$B$7:$B$96,A10,'03_Chi_tieu'!$I$7:$I$96,">0")=0,"",SUMIF('03_Chi_tieu'!$B$7:$B$96,A10,'03_Chi_tieu'!$I$7:$I$96)) | M10: =IF(ISNUMBER(L10),G10-L10,"") | N10: Xác nhận khả năng lặp lại trước khi xem xét trình cấp 2.
A11: G4 | B11: 4. Cấp 2 — 7 ngày đầu | C11: ='01_Thiet_lap'!$D$17 | D11: [Chưa chốt] | E11: [Chưa chốt] | F11: ='01_Thiet_lap'!$D$12 | G11: =C11*F11 | H11: =IF(ISNUMBER('01_Thiet_lap'!$D$24),C11*(F11-'01_Thiet_lap'!$D$24),"") | I11: =IF(ISNUMBER('01_Thiet_lap'!$D$24),C11*'01_Thiet_lap'!$D$24,"") | J11: Chờ xem xét | K11: =SUMIF('03_Chi_tieu'!$B$7:$B$96,A11,'03_Chi_tieu'!$S$7:$S$96) | L11: =IF(COUNTIFS('03_Chi_tieu'!$B$7:$B$96,A11,'03_Chi_tieu'!$I$7:$I$96,">0")=0,"",SUMIF('03_Chi_tieu'!$B$7:$B$96,A11,'03_Chi_tieu'!$I$7:$I$96)) | M11: =IF(ISNUMBER(L11),G11-L11,"") | N11: Phê duyệt riêng; phân bổ chi tiết chờ thống nhất.
A13: Khung tham chiếu đến hết hai chu kỳ cấp 1 | G13: =SUM(G7:G10) | J13: Có điều kiện; không mặc định là tổng ngân sách đã duyệt.
A15: Khung tham chiếu cấp 1 gồm 7 + 14 + 7 + 7 ngày hợp lệ. Chu kỳ bổ sung hoặc kéo dài cần được ghi nhận trong phạm vi thời gian và ngân sách được duyệt; không tự động cộng thêm ngân sách.
A17: Chi phí thực tế vẫn được tổng hợp kể cả ở ngày chưa đủ điều kiện. Một ngày chỉ được tính tiến độ khi có ngày thực, mã giai đoạn hợp lệ, xác nhận 'Hợp lệ', đủ bốn khoản chi (nhập 0 nếu không phát sinh), tổng chi > 0 và không trùng ngày.

Sheet 03_Chi_tieu
A1: NHẬT KÝ CHI TIÊU HẰNG NGÀY
A3: Mỗi ngày một dòng tổng hợp. Thay [Chưa chốt] bằng ngày thực; nhập 0 cho khoản không phát sinh. Dự phòng đã dùng là một phần của chi phí kênh, không cộng thêm vào tổng.
A6: Ngày chạy | B6: Giai đoạn | C6: Xác nhận ngày | D6: Khung đề xuất/ngày | E6: Thực chi LinkedIn | F6: Thực chi Search | G6: Thực chi tiếp thị lại | H6: Thử nghiệm khác | I6: Tổng chi quảng cáo | J6: Trong đó: dự phòng đã dùng | K6: Dự phòng còn giữ | L6: Chênh lệch so với khung/ngày | M6: Thuế/phí thực tế | N6: Tổng chi gồm thuế/phí | O6: Phê duyệt giai đoạn | P6: Nội dung cần rà soát | Q6: Lý do dùng dự phòng / ghi chú | R6: Hồ sơ / bằng chứng | S6: Ngày được tính (0/1)
A7: [Chưa chốt] | C7: Chưa xác nhận | D7: =IF(B7="","",IFERROR(VLOOKUP(B7,'02_Lo_trinh'!$A$7:$N$11,6,FALSE),"")) | I7: =IF(COUNT(E7:H7)=0,"",SUM(E7:H7)) | K7: =IF(OR(S7<>1,NOT(ISNUMBER(J7)),J7<0,J7>I7),"",IF(B7="G4",IF(ISNUMBER('01_Thiet_lap'!$D$24),MAX(0,'01_Thiet_lap'!$D$24-J7),""),MAX(0,'01_Thiet_lap'!$D$10-J7))) | L7: =IF(AND(ISNUMBER(I7),ISNUMBER(D7)),D7-I7,"") | N7: =IF(AND(ISNUMBER(I7),ISNUMBER(M7)),I7+M7,"") | O7: =IF(B7="","",IFERROR(VLOOKUP(B7,'02_Lo_trinh'!$A$7:$N$11,10,FALSE),"Cần chọn lại giai đoạn")) | P7: =IF(COUNT(E7:H7,M7)=0,"",IF(NOT(ISNUMBER(A7)),"Cần cập nhật ngày",IF(COUNTIF('02_Lo_trinh'!$A$7:$A$11,B7)<>1,"Cần chọn giai đoạn",IF(COUNTIF($A$7:$A$96,A7)>1,"Cần rà soát ngày trùng",IF(COUNT(E7:H7)<4,"Cần nhập đủ 4 khoản chi",IF(MIN(E7:H7)<0,"Cần rà soát khoản chi âm",IF(O7<>"Đã phê duyệt","Cần đối chiếu phê duyệt",IF(NOT(ISNUMBER(J7)),"Cần ghi phần dự phòng",IF(OR(J7<0,J7>I7),"Cần rà soát số tiền dự phòng",IF(AND(B7="G4",NOT(ISNUMBER('01_Thiet_lap'!$D$24))),"Cần chốt dự phòng cấp 2",IF(AND(B7<>"G4",J7>'01_Thiet_lap'!$D$10),"Cần rà soát mức dự phòng",IF(AND(B7="G4",ISNUMBER('01_Thiet_lap'!$D$24),J7>'01_Thiet_lap'!$D$24),"Cần rà soát dự phòng cấp 2",IF(AND(J7>0,Q7=""),"Cần bổ sung lý do dùng dự phòng",IF(C7<>"Hợp lệ","Chi phát sinh ngoài ngày hợp lệ",IF(NOT(ISNUMBER(M7)),"Chờ xác nhận thuế/phí",IF(I7>D7,"Cần rà soát mức chi trong ngày","Đã ghi nhận")))))))))))))))) | S7: =IF(AND(ISNUMBER(A7),COUNTIF('02_Lo_trinh'!$A$7:$A$11,B7)=1,C7="Hợp lệ",COUNT(E7:H7)=4,I7>0,COUNTIF($A$7:$A$96,A7)=1),1,0)
A8: [Chưa chốt] | C8: Chưa xác nhận | D8: =IF(B8="","",IFERROR(VLOOKUP(B8,'02_Lo_trinh'!$A$7:$N$11,6,FALSE),"")) | I8: =IF(COUNT(E8:H8)=0,"",SUM(E8:H8)) | K8: =IF(OR(S8<>1,NOT(ISNUMBER(J8)),J8<0,J8>I8),"",IF(B8="G4",IF(ISNUMBER('01_Thiet_lap'!$D$24),MAX(0,'01_Thiet_lap'!$D$24-J8),""),MAX(0,'01_Thiet_lap'!$D$10-J8))) | L8: =IF(AND(ISNUMBER(I8),ISNUMBER(D8)),D8-I8,"") | N8: =IF(AND(ISNUMBER(I8),ISNUMBER(M8)),I8+M8,"") | O8: =IF(B8="","",IFERROR(VLOOKUP(B8,'02_Lo_trinh'!$A$7:$N$11,10,FALSE),"Cần chọn lại giai đoạn")) | P8: =IF(COUNT(E8:H8,M8)=0,"",IF(NOT(ISNUMBER(A8)),"Cần cập nhật ngày",IF(COUNTIF('02_Lo_trinh'!$A$7:$A$11,B8)<>1,"Cần chọn giai đoạn",IF(COUNTIF($A$7:$A$96,A8)>1,"Cần rà soát ngày trùng",IF(COUNT(E8:H8)<4,"Cần nhập đủ 4 khoản chi",IF(MIN(E8:H8)<0,"Cần rà soát khoản chi âm",IF(O8<>"Đã phê duyệt","Cần đối chiếu phê duyệt",IF(NOT(ISNUMBER(J8)),"Cần ghi phần dự phòng",IF(OR(J8<0,J8>I8),"Cần rà soát số tiền dự phòng",IF(AND(B8="G4",NOT(ISNUMBER('01_Thiet_lap'!$D$24))),"Cần chốt dự phòng cấp 2",IF(AND(B8<>"G4",J8>'01_Thiet_lap'!$D$10),"Cần rà soát mức dự phòng",IF(AND(B8="G4",ISNUMBER('01_Thiet_lap'!$D$24),J8>'01_Thiet_lap'!$D$24),"Cần rà soát dự phòng cấp 2",IF(AND(J8>0,Q8=""),"Cần bổ sung lý do dùng dự phòng",IF(C8<>"Hợp lệ","Chi phát sinh ngoài ngày hợp lệ",IF(NOT(ISNUMBER(M8)),"Chờ xác nhận thuế/phí",IF(I8>D8,"Cần rà soát mức chi trong ngày","Đã ghi nhận")))))))))))))))) | S8: =IF(AND(ISNUMBER(A8),COUNTIF('02_Lo_trinh'!$A$7:$A$11,B8)=1,C8="Hợp lệ",COUNT(E8:H8)=4,I8>0,COUNTIF($A$7:$A$96,A8)=1),1,0)
A9: [Chưa chốt] | C9: Chưa xác nhận | D9: =IF(B9="","",IFERROR(VLOOKUP(B9,'02_Lo_trinh'!$A$7:$N$11,6,FALSE),"")) | I9: =IF(COUNT(E9:H9)=0,"",SUM(E9:H9)) | K9: =IF(OR(S9<>1,NOT(ISNUMBER(J9)),J9<0,J9>I9),"",IF(B9="G4",IF(ISNUMBER('01_Thiet_lap'!$D$24),MAX(0,'01_Thiet_lap'!$D$24-J9),""),MAX(0,'01_Thiet_lap'!$D$10-J9))) | L9: =IF(AND(ISNUMBER(I9),ISNUMBER(D9)),D9-I9,"") | N9: =IF(AND(ISNUMBER(I9),ISNUMBER(M9)),I9+M9,"") | O9: =IF(B9="","",IFERROR(VLOOKUP(B9,'02_Lo_trinh'!$A$7:$N$11,10,FALSE),"Cần chọn lại giai đoạn")) | P9: =IF(COUNT(E9:H9,M9)=0,"",IF(NOT(ISNUMBER(A9)),"Cần cập nhật ngày",IF(COUNTIF('02_Lo_trinh'!$A$7:$A$11,B9)<>1,"Cần chọn giai đoạn",IF(COUNTIF($A$7:$A$96,A9)>1,"Cần rà soát ngày trùng",IF(COUNT(E9:H9)<4,"Cần nhập đủ 4 khoản chi",IF(MIN(E9:H9)<0,"Cần rà soát khoản chi âm",IF(O9<>"Đã phê duyệt","Cần đối chiếu phê duyệt",IF(NOT(ISNUMBER(J9)),"Cần ghi phần dự phòng",IF(OR(J9<0,J9>I9),"Cần rà soát số tiền dự phòng",IF(AND(B9="G4",NOT(ISNUMBER('01_Thiet_lap'!$D$24))),"Cần chốt dự phòng cấp 2",IF(AND(B9<>"G4",J9>'01_Thiet_lap'!$D$10),"Cần rà soát mức dự phòng",IF(AND(B9="G4",ISNUMBER('01_Thiet_lap'!$D$24),J9>'01_Thiet_lap'!$D$24),"Cần rà soát dự phòng cấp 2",IF(AND(J9>0,Q9=""),"Cần bổ sung lý do dùng dự phòng",IF(C9<>"Hợp lệ","Chi phát sinh ngoài ngày hợp lệ",IF(NOT(ISNUMBER(M9)),"Chờ xác nhận thuế/phí",IF(I9>D9,"Cần rà soát mức chi trong ngày","Đã ghi nhận")))))))))))))))) | S9: =IF(AND(ISNUMBER(A9),COUNTIF('02_Lo_trinh'!$A$7:$A$11,B9)=1,C9="Hợp lệ",COUNT(E9:H9)=4,I9>0,COUNTIF($A$7:$A$96,A9)=1),1,0)
A10: [Chưa chốt] | C10: Chưa xác nhận | D10: =IF(B10="","",IFERROR(VLOOKUP(B10,'02_Lo_trinh'!$A$7:$N$11,6,FALSE),"")) | I10: =IF(COUNT(E10:H10)=0,"",SUM(E10:H10)) | K10: =IF(OR(S10<>1,NOT(ISNUMBER(J10)),J10<0,J10>I10),"",IF(B10="G4",IF(ISNUMBER('01_Thiet_lap'!$D$24),MAX(0,'01_Thiet_lap'!$D$24-J10),""),MAX(0,'01_Thiet_lap'!$D$10-J10))) | L10: =IF(AND(ISNUMBER(I10),ISNUMBER(D10)),D10-I10,"") | N10: =IF(AND(ISNUMBER(I10),ISNUMBER(M10)),I10+M10,"") | O10: =IF(B10="","",IFERROR(VLOOKUP(B10,'02_Lo_trinh'!$A$7:$N$11,10,FALSE),"Cần chọn lại giai đoạn")) | P10: =IF(COUNT(E10:H10,M10)=0,"",IF(NOT(ISNUMBER(A10)),"Cần cập nhật ngày",IF(COUNTIF('02_Lo_trinh'!$A$7:$A$11,B10)<>1,"Cần chọn giai đoạn",IF(COUNTIF($A$7:$A$96,A10)>1,"Cần rà soát ngày trùng",IF(COUNT(E10:H10)<4,"Cần nhập đủ 4 khoản chi",IF(MIN(E10:H10)<0,"Cần rà soát khoản chi âm",IF(O10<>"Đã phê duyệt","Cần đối chiếu phê duyệt",IF(NOT(ISNUMBER(J10)),"Cần ghi phần dự phòng",IF(OR(J10<0,J10>I10),"Cần rà soát số tiền dự phòng",IF(AND(B10="G4",NOT(ISNUMBER('01_Thiet_lap'!$D$24))),"Cần chốt dự phòng cấp 2",IF(AND(B10<>"G4",J10>'01_Thiet_lap'!$D$10),"Cần rà soát mức dự phòng",IF(AND(B10="G4",ISNUMBER('01_Thiet_lap'!$D$24),J10>'01_Thiet_lap'!$D$24),"Cần rà soát dự phòng cấp 2",IF(AND(J10>0,Q10=""),"Cần bổ sung lý do dùng dự phòng",IF(C10<>"Hợp lệ","Chi phát sinh ngoài ngày hợp lệ",IF(NOT(ISNUMBER(M10)),"Chờ xác nhận thuế/phí",IF(I10>D10,"Cần rà soát mức chi trong ngày","Đã ghi nhận")))))))))))))))) | S10: =IF(AND(ISNUMBER(A10),COUNTIF('02_Lo_trinh'!$A$7:$A$11,B10)=1,C10="Hợp lệ",COUNT(E10:H10)=4,I10>0,COUNTIF($A$7:$A$96,A10)=1),1,0)
A11: [Chưa chốt] | C11: Chưa xác nhận | D11: =IF(B11="","",IFERROR(VLOOKUP(B11,'02_Lo_trinh'!$A$7:$N$11,6,FALSE),"")) | I11: =IF(COUNT(E11:H11)=0,"",SUM(E11:H11)) | K11: =IF(OR(S11<>1,NOT(ISNUMBER(J11)),J11<0,J11>I11),"",IF(B11="G4",IF(ISNUMBER('01_Thiet_lap'!$D$24),MAX(0,'01_Thiet_lap'!$D$24-J11),""),MAX(0,'01_Thiet_lap'!$D$10-J11))) | L11: =IF(AND(ISNUMBER(I11),ISNUMBER(D11)),D11-I11,"") | N11: =IF(AND(ISNUMBER(I11),ISNUMBER(M11)),I11+M11,"") | O11: =IF(B11="","",IFERROR(VLOOKUP(B11,'02_Lo_trinh'!$A$7:$N$11,10,FALSE),"Cần chọn lại giai đoạn")) | P11: =IF(COUNT(E11:H11,M11)=0,"",IF(NOT(ISNUMBER(A11)),"Cần cập nhật ngày",IF(COUNTIF('02_Lo_trinh'!$A$7:$A$11,B11)<>1,"Cần chọn giai đoạn",IF(COUNTIF($A$7:$A$96,A11)>1,"Cần rà soát ngày trùng",IF(COUNT(E11:H11)<4,"Cần nhập đủ 4 khoản chi",IF(MIN(E11:H11)<0,"Cần rà soát khoản chi âm",IF(O11<>"Đã phê duyệt","Cần đối chiếu phê duyệt",IF(NOT(ISNUMBER(J11)),"Cần ghi phần dự phòng",IF(OR(J11<0,J11>I11),"Cần rà soát số tiền dự phòng",IF(AND(B11="G4",NOT(ISNUMBER('01_Thiet_lap'!$D$24))),"Cần chốt dự phòng cấp 2",IF(AND(B11<>"G4",J11>'01_Thiet_lap'!$D$10),"Cần rà soát mức dự phòng",IF(AND(B11="G4",ISNUMBER('01_Thiet_lap'!$D$24),J11>'01_Thiet_lap'!$D$24),"Cần rà soát dự phòng cấp 2",IF(AND(J11>0,Q11=""),"Cần bổ sung lý do dùng dự phòng",IF(C11<>"Hợp lệ","Chi phát sinh ngoài ngày hợp lệ",IF(NOT(ISNUMBER(M11)),"Chờ xác nhận thuế/phí",IF(I11>D11,"Cần rà soát mức chi trong ngày","Đã ghi nhận")))))))))))))))) | S11: =IF(AND(ISNUMBER(A11),COUNTIF('02_Lo_trinh'!$A$7:$A$11,B11)=1,C11="Hợp lệ",COUNT(E11:H11)=4,I11>0,COUNTIF($A$7:$A$96,A11)=1),1,0)
A12: [Chưa chốt] | C12: Chưa xác nhận | D12: =IF(B12="","",IFERROR(VLOOKUP(B12,'02_Lo_trinh'!$A$7:$N$11,6,FALSE),"")) | I12: =IF(COUNT(E12:H12)=0,"",SUM(E12:H12)) | K12: =IF(OR(S12<>1,NOT(ISNUMBER(J12)),J12<0,J12>I12),"",IF(B12="G4",IF(ISNUMBER('01_Thiet_lap'!$D$24),MAX(0,'01_Thiet_lap'!$D$24-J12),""),MAX(0,'01_Thiet_lap'!$D$10-J12))) | L12: =IF(AND(ISNUMBER(I12),ISNUMBER(D12)),D12-I12,"") | N12: =IF(AND(ISNUMBER(I12),ISNUMBER(M12)),I12+M12,"") | O12: =IF(B12="","",IFERROR(VLOOKUP(B12,'02_Lo_trinh'!$A$7:$N$11,10,FALSE),"Cần chọn lại giai đoạn")) | P12: =IF(COUNT(E12:H12,M12)=0,"",IF(NOT(ISNUMBER(A12)),"Cần cập nhật ngày",IF(COUNTIF('02_Lo_trinh'!$A$7:$A$11,B12)<>1,"Cần chọn giai đoạn",IF(COUNTIF($A$7:$A$96,A12)>1,"Cần rà soát ngày trùng",IF(COUNT(E12:H12)<4,"Cần nhập đủ 4 khoản chi",IF(MIN(E12:H12)<0,"Cần rà soát khoản chi âm",IF(O12<>"Đã phê duyệt","Cần đối chiếu phê duyệt",IF(NOT(ISNUMBER(J12)),"Cần ghi phần dự phòng",IF(OR(J12<0,J12>I12),"Cần rà soát số tiền dự phòng",IF(AND(B12="G4",NOT(ISNUMBER('01_Thiet_lap'!$D$24))),"Cần chốt dự phòng cấp 2",IF(AND(B12<>"G4",J12>'01_Thiet_lap'!$D$10),"Cần rà soát mức dự phòng",IF(AND(B12="G4",ISNUMBER('01_Thiet_lap'!$D$24),J12>'01_Thiet_lap'!$D$24),"Cần rà soát dự phòng cấp 2",IF(AND(J12>0,Q12=""),"Cần bổ sung lý do dùng dự phòng",IF(C12<>"Hợp lệ","Chi phát sinh ngoài ngày hợp lệ",IF(NOT(ISNUMBER(M12)),"Chờ xác nhận thuế/phí",IF(I12>D12,"Cần rà soát mức chi trong ngày","Đã ghi nhận")))))))))))))))) | S12: =IF(AND(ISNUMBER(A12),COUNTIF('02_Lo_trinh'!$A$7:$A$11,B12)=1,C12="Hợp lệ",COUNT(E12:H12)=4,I12>0,COUNTIF($A$7:$A$96,A12)=1),1,0)
A13: [Chưa chốt] | C13: Chưa xác nhận | D13: =IF(B13="","",IFERROR(VLOOKUP(B13,'02_Lo_trinh'!$A$7:$N$11,6,FALSE),"")) | I13: =IF(COUNT(E13:H13)=0,"",SUM(E13:H13)) | K13: =IF(OR(S13<>1,NOT(ISNUMBER(J13)),J13<0,J13>I13),"",IF(B13="G4",IF(ISNUMBER('01_Thiet_lap'!$D$24),MAX(0,'01_Thiet_lap'!$D$24-J13),""),MAX(0,'01_Thiet_lap'!$D$10-J13))) | L13: =IF(AND(ISNUMBER(I13),ISNUMBER(D13)),D13-I13,"") | N13: =IF(AND(ISNUMBER(I13),ISNUMBER(M13)),I13+M13,"") | O13: =IF(B13="","",IFERROR(VLOOKUP(B13,'02_Lo_trinh'!$A$7:$N$11,10,FALSE),"Cần chọn lại giai đoạn")) | P13: =IF(COUNT(E13:H13,M13)=0,"",IF(NOT(ISNUMBER(A13)),"Cần cập nhật ngày",IF(COUNTIF('02_Lo_trinh'!$A$7:$A$11,B13)<>1,"Cần chọn giai đoạn",IF(COUNTIF($A$7:$A$96,A13)>1,"Cần rà soát ngày trùng",IF(COUNT(E13:H13)<4,"Cần nhập đủ 4 khoản chi",IF(MIN(E13:H13)<0,"Cần rà soát khoản chi âm",IF(O13<>"Đã phê duyệt","Cần đối chiếu phê duyệt",IF(NOT(ISNUMBER(J13)),"Cần ghi phần dự phòng",IF(OR(J13<0,J13>I13),"Cần rà soát số tiền dự phòng",IF(AND(B13="G4",NOT(ISNUMBER('01_Thiet_lap'!$D$24))),"Cần chốt dự phòng cấp 2",IF(AND(B13<>"G4",J13>'01_Thiet_lap'!$D$10),"Cần rà soát mức dự phòng",IF(AND(B13="G4",ISNUMBER('01_Thiet_lap'!$D$24),J13>'01_Thiet_lap'!$D$24),"Cần rà soát dự phòng cấp 2",IF(AND(J13>0,Q13=""),"Cần bổ sung lý do dùng dự phòng",IF(C13<>"Hợp lệ","Chi phát sinh ngoài ngày hợp lệ",IF(NOT(ISNUMBER(M13)),"Chờ xác nhận thuế/phí",IF(I13>D13,"Cần rà soát mức chi trong ngày","Đã ghi nhận")))))))))))))))) | S13: =IF(AND(ISNUMBER(A13),COUNTIF('02_Lo_trinh'!$A$7:$A$11,B13)=1,C13="Hợp lệ",COUNT(E13:H13)=4,I13>0,COUNTIF($A$7:$A$96,A13)=1),1,0)
A14: [Chưa chốt] | C14: Chưa xác nhận | D14: =IF(B14="","",IFERROR(VLOOKUP(B14,'02_Lo_trinh'!$A$7:$N$11,6,FALSE),"")) | I14: =IF(COUNT(E14:H14)=0,"",SUM(E14:H14)) | K14: =IF(OR(S14<>1,NOT(ISNUMBER(J14)),J14<0,J14>I14),"",IF(B14="G4",IF(ISNUMBER('01_Thiet_lap'!$D$24),MAX(0,'01_Thiet_lap'!$D$24-J14),""),MAX(0,'01_Thiet_lap'!$D$10-J14))) | L14: =IF(AND(ISNUMBER(I14),ISNUMBER(D14)),D14-I14,"") | N14: =IF(AND(ISNUMBER(I14),ISNUMBER(M14)),I14+M14,"") | O14: =IF(B14="","",IFERROR(VLOOKUP(B14,'02_Lo_trinh'!$A$7:$N$11,10,FALSE),"Cần chọn lại giai đoạn")) | P14: =IF(COUNT(E14:H14,M14)=0,"",IF(NOT(ISNUMBER(A14)),"Cần cập nhật ngày",IF(COUNTIF('02_Lo_trinh'!$A$7:$A$11,B14)<>1,"Cần chọn giai đoạn",IF(COUNTIF($A$7:$A$96,A14)>1,"Cần rà soát ngày trùng",IF(COUNT(E14:H14)<4,"Cần nhập đủ 4 khoản chi",IF(MIN(E14:H14)<0,"Cần rà soát khoản chi âm",IF(O14<>"Đã phê duyệt","Cần đối chiếu phê duyệt",IF(NOT(ISNUMBER(J14)),"Cần ghi phần dự phòng",IF(OR(J14<0,J14>I14),"Cần rà soát số tiền dự phòng",IF(AND(B14="G4",NOT(ISNUMBER('01_Thiet_lap'!$D$24))),"Cần chốt dự phòng cấp 2",IF(AND(B14<>"G4",J14>'01_Thiet_lap'!$D$10),"Cần rà soát mức dự phòng",IF(AND(B14="G4",ISNUMBER('01_Thiet_lap'!$D$24),J14>'01_Thiet_lap'!$D$24),"Cần rà soát dự phòng cấp 2",IF(AND(J14>0,Q14=""),"Cần bổ sung lý do dùng dự phòng",IF(C14<>"Hợp lệ","Chi phát sinh ngoài ngày hợp lệ",IF(NOT(ISNUMBER(M14)),"Chờ xác nhận thuế/phí",IF(I14>D14,"Cần rà soát mức chi trong ngày","Đã ghi nhận")))))))))))))))) | S14: =IF(AND(ISNUMBER(A14),COUNTIF('02_Lo_trinh'!$A$7:$A$11,B14)=1,C14="Hợp lệ",COUNT(E14:H14)=4,I14>0,COUNTIF($A$7:$A$96,A14)=1),1,0)
A15: [Chưa chốt] | C15: Chưa xác nhận | D15: =IF(B15="","",IFERROR(VLOOKUP(B15,'02_Lo_trinh'!$A$7:$N$11,6,FALSE),"")) | I15: =IF(COUNT(E15:H15)=0,"",SUM(E15:H15)) | K15: =IF(OR(S15<>1,NOT(ISNUMBER(J15)),J15<0,J15>I15),"",IF(B15="G4",IF(ISNUMBER('01_Thiet_lap'!$D$24),MAX(0,'01_Thiet_lap'!$D$24-J15),""),MAX(0,'01_Thiet_lap'!$D$10-J15))) | L15: =IF(AND(ISNUMBER(I15),ISNUMBER(D15)),D15-I15,"") | N15: =IF(AND(ISNUMBER(I15),ISNUMBER(M15)),I15+M15,"") | O15: =IF(B15="","",IFERROR(VLOOKUP(B15,'02_Lo_trinh'!$A$7:$N$11,10,FALSE),"Cần chọn lại giai đoạn")) | P15: =IF(COUNT(E15:H15,M15)=0,"",IF(NOT(ISNUMBER(A15)),"Cần cập nhật ngày",IF(COUNTIF('02_Lo_trinh'!$A$7:$A$11,B15)<>1,"Cần chọn giai đoạn",IF(COUNTIF($A$7:$A$96,A15)>1,"Cần rà soát ngày trùng",IF(COUNT(E15:H15)<4,"Cần nhập đủ 4 khoản chi",IF(MIN(E15:H15)<0,"Cần rà soát khoản chi âm",IF(O15<>"Đã phê duyệt","Cần đối chiếu phê duyệt",IF(NOT(ISNUMBER(J15)),"Cần ghi phần dự phòng",IF(OR(J15<0,J15>I15),"Cần rà soát số tiền dự phòng",IF(AND(B15="G4",NOT(ISNUMBER('01_Thiet_lap'!$D$24))),"Cần chốt dự phòng cấp 2",IF(AND(B15<>"G4",J15>'01_Thiet_lap'!$D$10),"Cần rà soát mức dự phòng",IF(AND(B15="G4",ISNUMBER('01_Thiet_lap'!$D$24),J15>'01_Thiet_lap'!$D$24),"Cần rà soát dự phòng cấp 2",IF(AND(J15>0,Q15=""),"Cần bổ sung lý do dùng dự phòng",IF(C15<>"Hợp lệ","Chi phát sinh ngoài ngày hợp lệ",IF(NOT(ISNUMBER(M15)),"Chờ xác nhận thuế/phí",IF(I15>D15,"Cần rà soát mức chi trong ngày","Đã ghi nhận")))))))))))))))) | S15: =IF(AND(ISNUMBER(A15),COUNTIF('02_Lo_trinh'!$A$7:$A$11,B15)=1,C15="Hợp lệ",COUNT(E15:H15)=4,I15>0,COUNTIF($A$7:$A$96,A15)=1),1,0)
A16: [Chưa chốt] | C16: Chưa xác nhận | D16: =IF(B16="","",IFERROR(VLOOKUP(B16,'02_Lo_trinh'!$A$7:$N$11,6,FALSE),"")) | I16: =IF(COUNT(E16:H16)=0,"",SUM(E16:H16)) | K16: =IF(OR(S16<>1,NOT(ISNUMBER(J16)),J16<0,J16>I16),"",IF(B16="G4",IF(ISNUMBER('01_Thiet_lap'!$D$24),MAX(0,'01_Thiet_lap'!$D$24-J16),""),MAX(0,'01_Thiet_lap'!$D$10-J16))) | L16: =IF(AND(ISNUMBER(I16),ISNUMBER(D16)),D16-I16,"") | N16: =IF(AND(ISNUMBER(I16),ISNUMBER(M16)),I16+M16,"") | O16: =IF(B16="","",IFERROR(VLOOKUP(B16,'02_Lo_trinh'!$A$7:$N$11,10,FALSE),"Cần chọn lại giai đoạn")) | P16: =IF(COUNT(E16:H16,M16)=0,"",IF(NOT(ISNUMBER(A16)),"Cần cập nhật ngày",IF(COUNTIF('02_Lo_trinh'!$A$7:$A$11,B16)<>1,"Cần chọn giai đoạn",IF(COUNTIF($A$7:$A$96,A16)>1,"Cần rà soát ngày trùng",IF(COUNT(E16:H16)<4,"Cần nhập đủ 4 khoản chi",IF(MIN(E16:H16)<0,"Cần rà soát khoản chi âm",IF(O16<>"Đã phê duyệt","Cần đối chiếu phê duyệt",IF(NOT(ISNUMBER(J16)),"Cần ghi phần dự phòng",IF(OR(J16<0,J16>I16),"Cần rà soát số tiền dự phòng",IF(AND(B16="G4",NOT(ISNUMBER('01_Thiet_lap'!$D$24))),"Cần chốt dự phòng cấp 2",IF(AND(B16<>"G4",J16>'01_Thiet_lap'!$D$10),"Cần rà soát mức dự phòng",IF(AND(B16="G4",ISNUMBER('01_Thiet_lap'!$D$24),J16>'01_Thiet_lap'!$D$24),"Cần rà soát dự phòng cấp 2",IF(AND(J16>0,Q16=""),"Cần bổ sung lý do dùng dự phòng",IF(C16<>"Hợp lệ","Chi phát sinh ngoài ngày hợp lệ",IF(NOT(ISNUMBER(M16)),"Chờ xác nhận thuế/phí",IF(I16>D16,"Cần rà soát mức chi trong ngày","Đã ghi nhận")))))))))))))))) | S16: =IF(AND(ISNUMBER(A16),COUNTIF('02_Lo_trinh'!$A$7:$A$11,B16)=1,C16="Hợp lệ",COUNT(E16:H16)=4,I16>0,COUNTIF($A$7:$A$96,A16)=1),1,0)
A17: [Chưa chốt] | C17: Chưa xác nhận | D17: =IF(B17="","",IFERROR(VLOOKUP(B17,'02_Lo_trinh'!$A$7:$N$11,6,FALSE),"")) | I17: =IF(COUNT(E17:H17)=0,"",SUM(E17:H17)) | K17: =IF(OR(S17<>1,NOT(ISNUMBER(J17)),J17<0,J17>I17),"",IF(B17="G4",IF(ISNUMBER('01_Thiet_lap'!$D$24),MAX(0,'01_Thiet_lap'!$D$24-J17),""),MAX(0,'01_Thiet_lap'!$D$10-J17))) | L17: =IF(AND(ISNUMBER(I17),ISNUMBER(D17)),D17-I17,"") | N17: =IF(AND(ISNUMBER(I17),ISNUMBER(M17)),I17+M17,"") | O17: =IF(B17="","",IFERROR(VLOOKUP(B17,'02_Lo_trinh'!$A$7:$N$11,10,FALSE),"Cần chọn lại giai đoạn")) | P17: =IF(COUNT(E17:H17,M17)=0,"",IF(NOT(ISNUMBER(A17)),"Cần cập nhật ngày",IF(COUNTIF('02_Lo_trinh'!$A$7:$A$11,B17)<>1,"Cần chọn giai đoạn",IF(COUNTIF($A$7:$A$96,A17)>1,"Cần rà soát ngày trùng",IF(COUNT(E17:H17)<4,"Cần nhập đủ 4 khoản chi",IF(MIN(E17:H17)<0,"Cần rà soát khoản chi âm",IF(O17<>"Đã phê duyệt","Cần đối chiếu phê duyệt",IF(NOT(ISNUMBER(J17)),"Cần ghi phần dự phòng",IF(OR(J17<0,J17>I17),"Cần rà soát số tiền dự phòng",IF(AND(B17="G4",NOT(ISNUMBER('01_Thiet_lap'!$D$24))),"Cần chốt dự phòng cấp 2",IF(AND(B17<>"G4",J17>'01_Thiet_lap'!$D$10),"Cần rà soát mức dự phòng",IF(AND(B17="G4",ISNUMBER('01_Thiet_lap'!$D$24),J17>'01_Thiet_lap'!$D$24),"Cần rà soát dự phòng cấp 2",IF(AND(J17>0,Q17=""),"Cần bổ sung lý do dùng dự phòng",IF(C17<>"Hợp lệ","Chi phát sinh ngoài ngày hợp lệ",IF(NOT(ISNUMBER(M17)),"Chờ xác nhận thuế/phí",IF(I17>D17,"Cần rà soát mức chi trong ngày","Đã ghi nhận")))))))))))))))) | S17: =IF(AND(ISNUMBER(A17),COUNTIF('02_Lo_trinh'!$A$7:$A$11,B17)=1,C17="Hợp lệ",COUNT(E17:H17)=4,I17>0,COUNTIF($A$7:$A$96,A17)=1),1,0)
A18: [Chưa chốt] | C18: Chưa xác nhận | D18: =IF(B18="","",IFERROR(VLOOKUP(B18,'02_Lo_trinh'!$A$7:$N$11,6,FALSE),"")) | I18: =IF(COUNT(E18:H18)=0,"",SUM(E18:H18)) | K18: =IF(OR(S18<>1,NOT(ISNUMBER(J18)),J18<0,J18>I18),"",IF(B18="G4",IF(ISNUMBER('01_Thiet_lap'!$D$24),MAX(0,'01_Thiet_lap'!$D$24-J18),""),MAX(0,'01_Thiet_lap'!$D$10-J18))) | L18: =IF(AND(ISNUMBER(I18),ISNUMBER(D18)),D18-I18,"") | N18: =IF(AND(ISNUMBER(I18),ISNUMBER(M18)),I18+M18,"") | O18: =IF(B18="","",IFERROR(VLOOKUP(B18,'02_Lo_trinh'!$A$7:$N$11,10,FALSE),"Cần chọn lại giai đoạn")) | P18: =IF(COUNT(E18:H18,M18)=0,"",IF(NOT(ISNUMBER(A18)),"Cần cập nhật ngày",IF(COUNTIF('02_Lo_trinh'!$A$7:$A$11,B18)<>1,"Cần chọn giai đoạn",IF(COUNTIF($A$7:$A$96,A18)>1,"Cần rà soát ngày trùng",IF(COUNT(E18:H18)<4,"Cần nhập đủ 4 khoản chi",IF(MIN(E18:H18)<0,"Cần rà soát khoản chi âm",IF(O18<>"Đã phê duyệt","Cần đối chiếu phê duyệt",IF(NOT(ISNUMBER(J18)),"Cần ghi phần dự phòng",IF(OR(J18<0,J18>I18),"Cần rà soát số tiền dự phòng",IF(AND(B18="G4",NOT(ISNUMBER('01_Thiet_lap'!$D$24))),"Cần chốt dự phòng cấp 2",IF(AND(B18<>"G4",J18>'01_Thiet_lap'!$D$10),"Cần rà soát mức dự phòng",IF(AND(B18="G4",ISNUMBER('01_Thiet_lap'!$D$24),J18>'01_Thiet_lap'!$D$24),"Cần rà soát dự phòng cấp 2",IF(AND(J18>0,Q18=""),"Cần bổ sung lý do dùng dự phòng",IF(C18<>"Hợp lệ","Chi phát sinh ngoài ngày hợp lệ",IF(NOT(ISNUMBER(M18)),"Chờ xác nhận thuế/phí",IF(I18>D18,"Cần rà soát mức chi trong ngày","Đã ghi nhận")))))))))))))))) | S18: =IF(AND(ISNUMBER(A18),COUNTIF('02_Lo_trinh'!$A$7:$A$11,B18)=1,C18="Hợp lệ",COUNT(E18:H18)=4,I18>0,COUNTIF($A$7:$A$96,A18)=1),1,0)
... A96: [Chưa chốt] | C96: Chưa xác nhận | D96: =IF(B96="","",IFERROR(VLOOKUP(B96,'02_Lo_trinh'!$A$7:$N$11,6,FALSE),"")) | I96: =IF(COUNT(E96:H96)=0,"",SUM(E96:H96)) | K96: =IF(OR(S96<>1,NOT(ISNUMBER(J96)),J96<0,J96>I96),"",IF(B96="G4",IF(ISNUMBER('01_Thiet_lap'!$D$24),MAX(0,'01_Thiet_lap'!$D$24-J96),""),MAX(0,'01_Thiet_lap'!$D$10-J96))) | L96: =IF(AND(ISNUMBER(I96),ISNUMBER(D96)),D96-I96,"") | N96: =IF(AND(ISNUMBER(I96),ISNUMBER(M96)),I96+M96,"") | O96: =IF(B96="","",IFERROR(VLOOKUP(B96,'02_Lo_trinh'!$A$7:$N$11,10,FALSE),"Cần chọn lại giai đoạn")) | P96: =IF(COUNT(E96:H96,M96)=0,"",IF(NOT(ISNUMBER(A96)),"Cần cập nhật ngày",IF(COUNTIF('02_Lo_trinh'!$A$7:$A$11,B96)<>1,"Cần chọn giai đoạn",IF(COUNTIF($A$7:$A$96,A96)>1,"Cần rà soát ngày trùng",IF(COUNT(E96:H96)<4,"Cần nhập đủ 4 khoản chi",IF(MIN(E96:H96)<0,"Cần rà soát khoản chi âm",IF(O96<>"Đã phê duyệt","Cần đối chiếu phê duyệt",IF(NOT(ISNUMBER(J96)),"Cần ghi phần dự phòng",IF(OR(J96<0,J96>I96),"Cần rà soát số tiền dự phòng",IF(AND(B96="G4",NOT(ISNUMBER('01_Thiet_lap'!$D$24))),"Cần chốt dự phòng cấp 2",IF(AND(B96<>"G4",J96>'01_Thiet_lap'!$D$10),"Cần rà soát mức dự phòng",IF(AND(B96="G4",ISNUMBER('01_Thiet_lap'!$D$24),J96>'01_Thiet_lap'!$D$24),"Cần rà soát dự phòng cấp 2",IF(AND(J96>0,Q96=""),"Cần bổ sung lý do dùng dự phòng",IF(C96<>"Hợp lệ","Chi phát sinh ngoài ngày hợp lệ",IF(NOT(ISNUMBER(M96)),"Chờ xác nhận thuế/phí",IF(I96>D96,"Cần rà soát mức chi trong ngày","Đã ghi nhận")))))))))))))))) | S96: =IF(AND(ISNUMBER(A96),COUNTIF('02_Lo_trinh'!$A$7:$A$11,B96)=1,C96="Hợp lệ",COUNT(E96:H96)=4,I96>0,COUNTIF($A$7:$A$96,A96)=1),1,0)
A98: Khung/ngày là mốc quản trị bình quân. Chênh lệch theo ngày cần được xem cùng chi tiêu lũy kế và phạm vi phê duyệt. Tổng gồm thuế/phí chỉ hiện sau khi khoản thuế/phí đã được nhập, kể cả bằng 0.
A100: Dự phòng còn giữ chỉ tính trên ngày hợp lệ có thông tin dự phòng đầy đủ; không mặc định được chuyển sang ngày sau. Dòng có chi nhưng thiếu ngày/mã vẫn nằm trong tổng chi toàn chiến dịch và được gắn nội dung cần rà soát.

Sheet 04_Danh_gia
A1: ĐÁNH GIÁ THEO CHU KỲ & HỒ SƠ ĐỐI CHIẾU
A3: Mỗi kỳ có các tiêu chí tham chiếu; chỉ cập nhật tiêu chí phù hợp với quyết định đang xem xét. Ô trống không được hiểu là đạt. Nhận định sơ bộ không thay thế phê duyệt.
A5: Cấp 1: cải thiện ≥20% HOẶC giảm chi phí ≥15% với chất lượng tương đương. Cấp 2: xem xét cả hai chu kỳ cấp 1, mức suy giảm và dư địa đúng tệp.
A6: Kỳ | B6: Tiêu chí | C6: Ngày đánh giá | D6: Mốc đối chiếu / tổng quan sát | E6: Kỳ hiện tại / đúng chủ đề | F6: Kết quả tính | G6: Mốc tham chiếu | H6: Nhận định sơ bộ | I6: Bằng chứng / nguồn đối chiếu | J6: Ghi chú / định nghĩa chỉ số
A7: KY01 | B7: Đúng nhóm doanh nghiệp và vai trò | C7: [Chưa chốt] | F7: =IF(E7="","",E7) | G7: Đã xác nhận | H7: =IF(E7="","Chưa nhập dữ liệu",IF(NOT(ISNUMBER(C7)),"Cần cập nhật ngày",IF(I7="","Chờ hồ sơ đối chiếu",IF(E7="Đã xác nhận","Đạt mốc tham chiếu","Cần xem xét thêm")))) | J7: Đối chiếu dữ liệu tiếp cận với nhóm doanh nghiệp và vai trò đã thống nhất.
A8: KY01 | B8: Lượt nhấp Search liên quan đúng chủ đề | C8: [Chưa chốt] | F8: =IF(AND(ISNUMBER(D8),ISNUMBER(E8),D8>0,E8>=0),E8/D8,"") | G8: ='01_Thiet_lap'!$D$18 | H8: =IF(COUNT(D8:E8)=0,"Chưa nhập dữ liệu",IF(NOT(ISNUMBER(F8)),"Cần rà soát số liệu",IF(NOT(ISNUMBER(C8)),"Cần cập nhật ngày",IF(E8>D8,"Cần rà soát số liệu",IF(D8<'01_Thiet_lap'!$D$23,"Cần thêm dữ liệu quan sát",IF(I8="","Chờ hồ sơ đối chiếu",IF(F8>=G8,"Đạt mốc tham chiếu","Cần xem xét thêm"))))))) | J8: Cột D: tổng nhấp được kiểm tra. Cột E: nhấp đúng chủ đề. Mốc 7/10 là tham chiếu vận hành, không khẳng định độ tin cậy thống kê.
A9: KY01 | B9: Duy trì mức quan tâm so với ban đầu | C9: [Chưa chốt] | F9: =IF(AND(ISNUMBER(D9),ISNUMBER(E9),D9>0,E9>=0),E9/D9,"") | G9: ='01_Thiet_lap'!$D$19 | H9: =IF(COUNT(D9:E9)=0,"Chưa nhập dữ liệu",IF(NOT(ISNUMBER(F9)),"Cần rà soát số liệu",IF(NOT(ISNUMBER(C9)),"Cần cập nhật ngày",IF(OR('01_Thiet_lap'!$D$28="",'01_Thiet_lap'!$D$28="[Chưa thống nhất]"),"Chờ thống nhất chỉ số",IF(I9="","Chờ hồ sơ đối chiếu",IF(F9>=G9,"Đạt mốc tham chiếu","Cần xem xét thêm")))))) | J9: D/E dùng cùng chỉ số quan tâm tại Thiết lập. Kết quả = hiện tại / ban đầu.
A10: KY01 | B10: Cải thiện của phương án được ưu tiên | C10: [Chưa chốt] | F10: =IF(AND(ISNUMBER(D10),ISNUMBER(E10),D10>0,E10>=0),E10/D10-1,"") | G10: ='01_Thiet_lap'!$D$20 | H10: =IF(COUNT(D10:E10)=0,"Chưa nhập dữ liệu",IF(NOT(ISNUMBER(F10)),"Cần rà soát số liệu",IF(NOT(ISNUMBER(C10)),"Cần cập nhật ngày",IF(OR('01_Thiet_lap'!$D$29="",'01_Thiet_lap'!$D$29="[Chưa thống nhất]"),"Chờ thống nhất chỉ số",IF(I10="","Chờ hồ sơ đối chiếu",IF(F10>=G10,"Đạt mốc tham chiếu","Cần xem xét thêm")))))) | J10: D: phương án đối chiếu; E: phương án được ưu tiên. Dùng chỉ số tăng là tốt hơn. Tiêu chí này là một lựa chọn thay thế cho giảm chi phí.
A11: KY01 | B11: Giảm chi phí với chất lượng tương đương | C11: [Chưa chốt] | F11: =IF(AND(ISNUMBER(D11),ISNUMBER(E11),D11>0,E11>=0),1-E11/D11,"") | G11: ='01_Thiet_lap'!$D$21 | H11: =IF(COUNT(D11:E11)=0,"Chưa nhập dữ liệu",IF(NOT(ISNUMBER(F11)),"Cần rà soát số liệu",IF(NOT(ISNUMBER(C11)),"Cần cập nhật ngày",IF(OR('01_Thiet_lap'!$D$30="",'01_Thiet_lap'!$D$30="[Chưa thống nhất]"),"Chờ thống nhất chỉ số",IF(I11="","Chờ hồ sơ đối chiếu",IF(F11>=G11,"Đạt mốc tham chiếu","Cần xem xét thêm")))))) | J11: D/E cùng đơn vị chi phí. Mức giảm = 1 − hiện tại/đối chiếu. Cần kèm bằng chứng chất lượng tương đương.
A12: KY01 | B12: Chất lượng ổn định khi tăng phân bổ | C12: [Chưa chốt] | F12: =IF(E12="","",E12) | G12: Đã xác nhận | H12: =IF(E12="","Chưa nhập dữ liệu",IF(NOT(ISNUMBER(C12)),"Cần cập nhật ngày",IF(I12="","Chờ hồ sơ đối chiếu",IF(E12="Đã xác nhận","Đạt mốc tham chiếu","Cần xem xét thêm")))) | J12: Ghi bằng chứng chất lượng được duy trì; không chỉ dựa trên số lượng tương tác.
A13: KY01 | B13: Mức suy giảm sau mở rộng cấp 1 | C13: [Chưa chốt] | F13: =IF(AND(ISNUMBER(D13),ISNUMBER(E13),D13>0,E13>=0),MAX(0,1-E13/D13),"") | G13: ='01_Thiet_lap'!$D$22 | H13: =IF(COUNT(D13:E13)=0,"Chưa nhập dữ liệu",IF(NOT(ISNUMBER(F13)),"Cần rà soát số liệu",IF(NOT(ISNUMBER(C13)),"Cần cập nhật ngày",IF(OR('01_Thiet_lap'!$D$28="",'01_Thiet_lap'!$D$28="[Chưa thống nhất]"),"Chờ thống nhất chỉ số",IF(I13="","Chờ hồ sơ đối chiếu",IF(F13<=G13,"Đạt mốc tham chiếu","Cần xem xét thêm")))))) | J13: Dùng khi xét cấp 2. D: mốc đối chiếu đã thống nhất; E: kỳ hiện tại. Mức giảm = MAX(0; 1 − hiện tại/đối chiếu).
A14: KY01 | B14: Dư địa tiếp cận thêm đúng nhóm mục tiêu | C14: [Chưa chốt] | F14: =IF(E14="","",E14) | G14: Đã xác nhận | H14: =IF(E14="","Chưa nhập dữ liệu",IF(NOT(ISNUMBER(C14)),"Cần cập nhật ngày",IF(I14="","Chờ hồ sơ đối chiếu",IF(E14="Đã xác nhận","Đạt mốc tham chiếu","Cần xem xét thêm")))) | J14: Dùng khi xem xét mở rộng, đặc biệt cấp 2; đối chiếu phạm vi tệp và chất lượng tiếp cận.
A15: KY01 | B15: Độ tin cậy của đo lường và trang đích | C15: [Chưa chốt] | F15: =IF(E15="","",E15) | G15: Đã xác nhận | H15: =IF(E15="","Chưa nhập dữ liệu",IF(NOT(ISNUMBER(C15)),"Cần cập nhật ngày",IF(I15="","Chờ hồ sơ đối chiếu",IF(E15="Đã xác nhận","Đạt mốc tham chiếu","Cần xem xét thêm")))) | J15: Đối chiếu nguồn dữ liệu, trang đích, sự kiện và nơi tiếp nhận biểu mẫu.
A16: KY01 | B16: Điều kiện tiếp cận lại nhóm đã tương tác | C16: [Chưa chốt] | F16: =IF(E16="","",E16) | G16: Đã xác nhận / Không áp dụng | H16: =IF(E16="","Chưa nhập dữ liệu",IF(E16="Không áp dụng","Không áp dụng",IF(NOT(ISNUMBER(C16)),"Cần cập nhật ngày",IF(I16="","Chờ hồ sơ đối chiếu",IF(E16="Đã xác nhận","Đạt mốc tham chiếu","Cần xem xét thêm"))))) | J16: Chỉ áp dụng khi đề xuất tiếp thị lại. Có thể chọn 'Không áp dụng' nếu chưa sử dụng phương án này.
A17: KY02 | B17: Đúng nhóm doanh nghiệp và vai trò | C17: [Chưa chốt] | F17: =IF(E17="","",E17) | G17: Đã xác nhận | H17: =IF(E17="","Chưa nhập dữ liệu",IF(NOT(ISNUMBER(C17)),"Cần cập nhật ngày",IF(I17="","Chờ hồ sơ đối chiếu",IF(E17="Đã xác nhận","Đạt mốc tham chiếu","Cần xem xét thêm")))) | J17: Đối chiếu dữ liệu tiếp cận với nhóm doanh nghiệp và vai trò đã thống nhất.
A18: KY02 | B18: Lượt nhấp Search liên quan đúng chủ đề | C18: [Chưa chốt] | F18: =IF(AND(ISNUMBER(D18),ISNUMBER(E18),D18>0,E18>=0),E18/D18,"") | G18: ='01_Thiet_lap'!$D$18 | H18: =IF(COUNT(D18:E18)=0,"Chưa nhập dữ liệu",IF(NOT(ISNUMBER(F18)),"Cần rà soát số liệu",IF(NOT(ISNUMBER(C18)),"Cần cập nhật ngày",IF(E18>D18,"Cần rà soát số liệu",IF(D18<'01_Thiet_lap'!$D$23,"Cần thêm dữ liệu quan sát",IF(I18="","Chờ hồ sơ đối chiếu",IF(F18>=G18,"Đạt mốc tham chiếu","Cần xem xét thêm"))))))) | J18: Cột D: tổng nhấp được kiểm tra. Cột E: nhấp đúng chủ đề. Mốc 7/10 là tham chiếu vận hành, không khẳng định độ tin cậy thống kê.
A19: KY02 | B19: Duy trì mức quan tâm so với ban đầu | C19: [Chưa chốt] | F19: =IF(AND(ISNUMBER(D19),ISNUMBER(E19),D19>0,E19>=0),E19/D19,"") | G19: ='01_Thiet_lap'!$D$19 | H19: =IF(COUNT(D19:E19)=0,"Chưa nhập dữ liệu",IF(NOT(ISNUMBER(F19)),"Cần rà soát số liệu",IF(NOT(ISNUMBER(C19)),"Cần cập nhật ngày",IF(OR('01_Thiet_lap'!$D$28="",'01_Thiet_lap'!$D$28="[Chưa thống nhất]"),"Chờ thống nhất chỉ số",IF(I19="","Chờ hồ sơ đối chiếu",IF(F19>=G19,"Đạt mốc tham chiếu","Cần xem xét thêm")))))) | J19: D/E dùng cùng chỉ số quan tâm tại Thiết lập. Kết quả = hiện tại / ban đầu.
A20: KY02 | B20: Cải thiện của phương án được ưu tiên | C20: [Chưa chốt] | F20: =IF(AND(ISNUMBER(D20),ISNUMBER(E20),D20>0,E20>=0),E20/D20-1,"") | G20: ='01_Thiet_lap'!$D$20 | H20: =IF(COUNT(D20:E20)=0,"Chưa nhập dữ liệu",IF(NOT(ISNUMBER(F20)),"Cần rà soát số liệu",IF(NOT(ISNUMBER(C20)),"Cần cập nhật ngày",IF(OR('01_Thiet_lap'!$D$29="",'01_Thiet_lap'!$D$29="[Chưa thống nhất]"),"Chờ thống nhất chỉ số",IF(I20="","Chờ hồ sơ đối chiếu",IF(F20>=G20,"Đạt mốc tham chiếu","Cần xem xét thêm")))))) | J20: D: phương án đối chiếu; E: phương án được ưu tiên. Dùng chỉ số tăng là tốt hơn. Tiêu chí này là một lựa chọn thay thế cho giảm chi phí.
A21: KY02 | B21: Giảm chi phí với chất lượng tương đương | C21: [Chưa chốt] | F21: =IF(AND(ISNUMBER(D21),ISNUMBER(E21),D21>0,E21>=0),1-E21/D21,"") | G21: ='01_Thiet_lap'!$D$21 | H21: =IF(COUNT(D21:E21)=0,"Chưa nhập dữ liệu",IF(NOT(ISNUMBER(F21)),"Cần rà soát số liệu",IF(NOT(ISNUMBER(C21)),"Cần cập nhật ngày",IF(OR('01_Thiet_lap'!$D$30="",'01_Thiet_lap'!$D$30="[Chưa thống nhất]"),"Chờ thống nhất chỉ số",IF(I21="","Chờ hồ sơ đối chiếu",IF(F21>=G21,"Đạt mốc tham chiếu","Cần xem xét thêm")))))) | J21: D/E cùng đơn vị chi phí. Mức giảm = 1 − hiện tại/đối chiếu. Cần kèm bằng chứng chất lượng tương đương.
A22: KY02 | B22: Chất lượng ổn định khi tăng phân bổ | C22: [Chưa chốt] | F22: =IF(E22="","",E22) | G22: Đã xác nhận | H22: =IF(E22="","Chưa nhập dữ liệu",IF(NOT(ISNUMBER(C22)),"Cần cập nhật ngày",IF(I22="","Chờ hồ sơ đối chiếu",IF(E22="Đã xác nhận","Đạt mốc tham chiếu","Cần xem xét thêm")))) | J22: Ghi bằng chứng chất lượng được duy trì; không chỉ dựa trên số lượng tương tác.
A23: KY02 | B23: Mức suy giảm sau mở rộng cấp 1 | C23: [Chưa chốt] | F23: =IF(AND(ISNUMBER(D23),ISNUMBER(E23),D23>0,E23>=0),MAX(0,1-E23/D23),"") | G23: ='01_Thiet_lap'!$D$22 | H23: =IF(COUNT(D23:E23)=0,"Chưa nhập dữ liệu",IF(NOT(ISNUMBER(F23)),"Cần rà soát số liệu",IF(NOT(ISNUMBER(C23)),"Cần cập nhật ngày",IF(OR('01_Thiet_lap'!$D$28="",'01_Thiet_lap'!$D$28="[Chưa thống nhất]"),"Chờ thống nhất chỉ số",IF(I23="","Chờ hồ sơ đối chiếu",IF(F23<=G23,"Đạt mốc tham chiếu","Cần xem xét thêm")))))) | J23: Dùng khi xét cấp 2. D: mốc đối chiếu đã thống nhất; E: kỳ hiện tại. Mức giảm = MAX(0; 1 − hiện tại/đối chiếu).
A24: KY02 | B24: Dư địa tiếp cận thêm đúng nhóm mục tiêu | C24: [Chưa chốt] | F24: =IF(E24="","",E24) | G24: Đã xác nhận | H24: =IF(E24="","Chưa nhập dữ liệu",IF(NOT(ISNUMBER(C24)),"Cần cập nhật ngày",IF(I24="","Chờ hồ sơ đối chiếu",IF(E24="Đã xác nhận","Đạt mốc tham chiếu","Cần xem xét thêm")))) | J24: Dùng khi xem xét mở rộng, đặc biệt cấp 2; đối chiếu phạm vi tệp và chất lượng tiếp cận.
A25: KY02 | B25: Độ tin cậy của đo lường và trang đích | C25: [Chưa chốt] | F25: =IF(E25="","",E25) | G25: Đã xác nhận | H25: =IF(E25="","Chưa nhập dữ liệu",IF(NOT(ISNUMBER(C25)),"Cần cập nhật ngày",IF(I25="","Chờ hồ sơ đối chiếu",IF(E25="Đã xác nhận","Đạt mốc tham chiếu","Cần xem xét thêm")))) | J25: Đối chiếu nguồn dữ liệu, trang đích, sự kiện và nơi tiếp nhận biểu mẫu.
A26: KY02 | B26: Điều kiện tiếp cận lại nhóm đã tương tác | C26: [Chưa chốt] | F26: =IF(E26="","",E26) | G26: Đã xác nhận / Không áp dụng | H26: =IF(E26="","Chưa nhập dữ liệu",IF(E26="Không áp dụng","Không áp dụng",IF(NOT(ISNUMBER(C26)),"Cần cập nhật ngày",IF(I26="","Chờ hồ sơ đối chiếu",IF(E26="Đã xác nhận","Đạt mốc tham chiếu","Cần xem xét thêm"))))) | J26: Chỉ áp dụng khi đề xuất tiếp thị lại. Có thể chọn 'Không áp dụng' nếu chưa sử dụng phương án này.
A27: KY03 | B27: Đúng nhóm doanh nghiệp và vai trò | C27: [Chưa chốt] | F27: =IF(E27="","",E27) | G27: Đã xác nhận | H27: =IF(E27="","Chưa nhập dữ liệu",IF(NOT(ISNUMBER(C27)),"Cần cập nhật ngày",IF(I27="","Chờ hồ sơ đối chiếu",IF(E27="Đã xác nhận","Đạt mốc tham chiếu","Cần xem xét thêm")))) | J27: Đối chiếu dữ liệu tiếp cận với nhóm doanh nghiệp và vai trò đã thống nhất.
A28: KY03 | B28: Lượt nhấp Search liên quan đúng chủ đề | C28: [Chưa chốt] | F28: =IF(AND(ISNUMBER(D28),ISNUMBER(E28),D28>0,E28>=0),E28/D28,"") | G28: ='01_Thiet_lap'!$D$18 | H28: =IF(COUNT(D28:E28)=0,"Chưa nhập dữ liệu",IF(NOT(ISNUMBER(F28)),"Cần rà soát số liệu",IF(NOT(ISNUMBER(C28)),"Cần cập nhật ngày",IF(E28>D28,"Cần rà soát số liệu",IF(D28<'01_Thiet_lap'!$D$23,"Cần thêm dữ liệu quan sát",IF(I28="","Chờ hồ sơ đối chiếu",IF(F28>=G28,"Đạt mốc tham chiếu","Cần xem xét thêm"))))))) | J28: Cột D: tổng nhấp được kiểm tra. Cột E: nhấp đúng chủ đề. Mốc 7/10 là tham chiếu vận hành, không khẳng định độ tin cậy thống kê.
A29: KY03 | B29: Duy trì mức quan tâm so với ban đầu | C29: [Chưa chốt] | F29: =IF(AND(ISNUMBER(D29),ISNUMBER(E29),D29>0,E29>=0),E29/D29,"") | G29: ='01_Thiet_lap'!$D$19 | H29: =IF(COUNT(D29:E29)=0,"Chưa nhập dữ liệu",IF(NOT(ISNUMBER(F29)),"Cần rà soát số liệu",IF(NOT(ISNUMBER(C29)),"Cần cập nhật ngày",IF(OR('01_Thiet_lap'!$D$28="",'01_Thiet_lap'!$D$28="[Chưa thống nhất]"),"Chờ thống nhất chỉ số",IF(I29="","Chờ hồ sơ đối chiếu",IF(F29>=G29,"Đạt mốc tham chiếu","Cần xem xét thêm")))))) | J29: D/E dùng cùng chỉ số quan tâm tại Thiết lập. Kết quả = hiện tại / ban đầu.
A30: KY03 | B30: Cải thiện của phương án được ưu tiên | C30: [Chưa chốt] | F30: =IF(AND(ISNUMBER(D30),ISNUMBER(E30),D30>0,E30>=0),E30/D30-1,"") | G30: ='01_Thiet_lap'!$D$20 | H30: =IF(COUNT(D30:E30)=0,"Chưa nhập dữ liệu",IF(NOT(ISNUMBER(F30)),"Cần rà soát số liệu",IF(NOT(ISNUMBER(C30)),"Cần cập nhật ngày",IF(OR('01_Thiet_lap'!$D$29="",'01_Thiet_lap'!$D$29="[Chưa thống nhất]"),"Chờ thống nhất chỉ số",IF(I30="","Chờ hồ sơ đối chiếu",IF(F30>=G30,"Đạt mốc tham chiếu","Cần xem xét thêm")))))) | J30: D: phương án đối chiếu; E: phương án được ưu tiên. Dùng chỉ số tăng là tốt hơn. Tiêu chí này là một lựa chọn thay thế cho giảm chi phí.
A31: KY03 | B31: Giảm chi phí với chất lượng tương đương | C31: [Chưa chốt] | F31: =IF(AND(ISNUMBER(D31),ISNUMBER(E31),D31>0,E31>=0),1-E31/D31,"") | G31: ='01_Thiet_lap'!$D$21 | H31: =IF(COUNT(D31:E31)=0,"Chưa nhập dữ liệu",IF(NOT(ISNUMBER(F31)),"Cần rà soát số liệu",IF(NOT(ISNUMBER(C31)),"Cần cập nhật ngày",IF(OR('01_Thiet_lap'!$D$30="",'01_Thiet_lap'!$D$30="[Chưa thống nhất]"),"Chờ thống nhất chỉ số",IF(I31="","Chờ hồ sơ đối chiếu",IF(F31>=G31,"Đạt mốc tham chiếu","Cần xem xét thêm")))))) | J31: D/E cùng đơn vị chi phí. Mức giảm = 1 − hiện tại/đối chiếu. Cần kèm bằng chứng chất lượng tương đương.
A32: KY03 | B32: Chất lượng ổn định khi tăng phân bổ | C32: [Chưa chốt] | F32: =IF(E32="","",E32) | G32: Đã xác nhận | H32: =IF(E32="","Chưa nhập dữ liệu",IF(NOT(ISNUMBER(C32)),"Cần cập nhật ngày",IF(I32="","Chờ hồ sơ đối chiếu",IF(E32="Đã xác nhận","Đạt mốc tham chiếu","Cần xem xét thêm")))) | J32: Ghi bằng chứng chất lượng được duy trì; không chỉ dựa trên số lượng tương tác.
A33: KY03 | B33: Mức suy giảm sau mở rộng cấp 1 | C33: [Chưa chốt] | F33: =IF(AND(ISNUMBER(D33),ISNUMBER(E33),D33>0,E33>=0),MAX(0,1-E33/D33),"") | G33: ='01_Thiet_lap'!$D$22 | H33: =IF(COUNT(D33:E33)=0,"Chưa nhập dữ liệu",IF(NOT(ISNUMBER(F33)),"Cần rà soát số liệu",IF(NOT(ISNUMBER(C33)),"Cần cập nhật ngày",IF(OR('01_Thiet_lap'!$D$28="",'01_Thiet_lap'!$D$28="[Chưa thống nhất]"),"Chờ thống nhất chỉ số",IF(I33="","Chờ hồ sơ đối chiếu",IF(F33<=G33,"Đạt mốc tham chiếu","Cần xem xét thêm")))))) | J33: Dùng khi xét cấp 2. D: mốc đối chiếu đã thống nhất; E: kỳ hiện tại. Mức giảm = MAX(0; 1 − hiện tại/đối chiếu).
A34: KY03 | B34: Dư địa tiếp cận thêm đúng nhóm mục tiêu | C34: [Chưa chốt] | F34: =IF(E34="","",E34) | G34: Đã xác nhận | H34: =IF(E34="","Chưa nhập dữ liệu",IF(NOT(ISNUMBER(C34)),"Cần cập nhật ngày",IF(I34="","Chờ hồ sơ đối chiếu",IF(E34="Đã xác nhận","Đạt mốc tham chiếu","Cần xem xét thêm")))) | J34: Dùng khi xem xét mở rộng, đặc biệt cấp 2; đối chiếu phạm vi tệp và chất lượng tiếp cận.
A35: KY03 | B35: Độ tin cậy của đo lường và trang đích | C35: [Chưa chốt] | F35: =IF(E35="","",E35) | G35: Đã xác nhận | H35: =IF(E35="","Chưa nhập dữ liệu",IF(NOT(ISNUMBER(C35)),"Cần cập nhật ngày",IF(I35="","Chờ hồ sơ đối chiếu",IF(E35="Đã xác nhận","Đạt mốc tham chiếu","Cần xem xét thêm")))) | J35: Đối chiếu nguồn dữ liệu, trang đích, sự kiện và nơi tiếp nhận biểu mẫu.
A36: KY03 | B36: Điều kiện tiếp cận lại nhóm đã tương tác | C36: [Chưa chốt] | F36: =IF(E36="","",E36) | G36: Đã xác nhận / Không áp dụng | H36: =IF(E36="","Chưa nhập dữ liệu",IF(E36="Không áp dụng","Không áp dụng",IF(NOT(ISNUMBER(C36)),"Cần cập nhật ngày",IF(I36="","Chờ hồ sơ đối chiếu",IF(E36="Đã xác nhận","Đạt mốc tham chiếu","Cần xem xét thêm"))))) | J36: Chỉ áp dụng khi đề xuất tiếp thị lại. Có thể chọn 'Không áp dụng' nếu chưa sử dụng phương án này.
A37: KY04 | B37: Đúng nhóm doanh nghiệp và vai trò | C37: [Chưa chốt] | F37: =IF(E37="","",E37) | G37: Đã xác nhận | H37: =IF(E37="","Chưa nhập dữ liệu",IF(NOT(ISNUMBER(C37)),"Cần cập nhật ngày",IF(I37="","Chờ hồ sơ đối chiếu",IF(E37="Đã xác nhận","Đạt mốc tham chiếu","Cần xem xét thêm")))) | J37: Đối chiếu dữ liệu tiếp cận với nhóm doanh nghiệp và vai trò đã thống nhất.
A38: KY04 | B38: Lượt nhấp Search liên quan đúng chủ đề | C38: [Chưa chốt] | F38: =IF(AND(ISNUMBER(D38),ISNUMBER(E38),D38>0,E38>=0),E38/D38,"") | G38: ='01_Thiet_lap'!$D$18 | H38: =IF(COUNT(D38:E38)=0,"Chưa nhập dữ liệu",IF(NOT(ISNUMBER(F38)),"Cần rà soát số liệu",IF(NOT(ISNUMBER(C38)),"Cần cập nhật ngày",IF(E38>D38,"Cần rà soát số liệu",IF(D38<'01_Thiet_lap'!$D$23,"Cần thêm dữ liệu quan sát",IF(I38="","Chờ hồ sơ đối chiếu",IF(F38>=G38,"Đạt mốc tham chiếu","Cần xem xét thêm"))))))) | J38: Cột D: tổng nhấp được kiểm tra. Cột E: nhấp đúng chủ đề. Mốc 7/10 là tham chiếu vận hành, không khẳng định độ tin cậy thống kê.
A39: KY04 | B39: Duy trì mức quan tâm so với ban đầu | C39: [Chưa chốt] | F39: =IF(AND(ISNUMBER(D39),ISNUMBER(E39),D39>0,E39>=0),E39/D39,"") | G39: ='01_Thiet_lap'!$D$19 | H39: =IF(COUNT(D39:E39)=0,"Chưa nhập dữ liệu",IF(NOT(ISNUMBER(F39)),"Cần rà soát số liệu",IF(NOT(ISNUMBER(C39)),"Cần cập nhật ngày",IF(OR('01_Thiet_lap'!$D$28="",'01_Thiet_lap'!$D$28="[Chưa thống nhất]"),"Chờ thống nhất chỉ số",IF(I39="","Chờ hồ sơ đối chiếu",IF(F39>=G39,"Đạt mốc tham chiếu","Cần xem xét thêm")))))) | J39: D/E dùng cùng chỉ số quan tâm tại Thiết lập. Kết quả = hiện tại / ban đầu.
A40: KY04 | B40: Cải thiện của phương án được ưu tiên | C40: [Chưa chốt] | F40: =IF(AND(ISNUMBER(D40),ISNUMBER(E40),D40>0,E40>=0),E40/D40-1,"") | G40: ='01_Thiet_lap'!$D$20 | H40: =IF(COUNT(D40:E40)=0,"Chưa nhập dữ liệu",IF(NOT(ISNUMBER(F40)),"Cần rà soát số liệu",IF(NOT(ISNUMBER(C40)),"Cần cập nhật ngày",IF(OR('01_Thiet_lap'!$D$29="",'01_Thiet_lap'!$D$29="[Chưa thống nhất]"),"Chờ thống nhất chỉ số",IF(I40="","Chờ hồ sơ đối chiếu",IF(F40>=G40,"Đạt mốc tham chiếu","Cần xem xét thêm")))))) | J40: D: phương án đối chiếu; E: phương án được ưu tiên. Dùng chỉ số tăng là tốt hơn. Tiêu chí này là một lựa chọn thay thế cho giảm chi phí.
A41: KY04 | B41: Giảm chi phí với chất lượng tương đương | C41: [Chưa chốt] | F41: =IF(AND(ISNUMBER(D41),ISNUMBER(E41),D41>0,E41>=0),1-E41/D41,"") | G41: ='01_Thiet_lap'!$D$21 | H41: =IF(COUNT(D41:E41)=0,"Chưa nhập dữ liệu",IF(NOT(ISNUMBER(F41)),"Cần rà soát số liệu",IF(NOT(ISNUMBER(C41)),"Cần cập nhật ngày",IF(OR('01_Thiet_lap'!$D$30="",'01_Thiet_lap'!$D$30="[Chưa thống nhất]"),"Chờ thống nhất chỉ số",IF(I41="","Chờ hồ sơ đối chiếu",IF(F41>=G41,"Đạt mốc tham chiếu","Cần xem xét thêm")))))) | J41: D/E cùng đơn vị chi phí. Mức giảm = 1 − hiện tại/đối chiếu. Cần kèm bằng chứng chất lượng tương đương.
A42: KY04 | B42: Chất lượng ổn định khi tăng phân bổ | C42: [Chưa chốt] | F42: =IF(E42="","",E42) | G42: Đã xác nhận | H42: =IF(E42="","Chưa nhập dữ liệu",IF(NOT(ISNUMBER(C42)),"Cần cập nhật ngày",IF(I42="","Chờ hồ sơ đối chiếu",IF(E42="Đã xác nhận","Đạt mốc tham chiếu","Cần xem xét thêm")))) | J42: Ghi bằng chứng chất lượng được duy trì; không chỉ dựa trên số lượng tương tác.
...

Sheet 05_Bao_cao_tuan
A1: BÁO CÁO TUẦN & ĐỀ XUẤT KỲ TIẾP THEO
A3: Điền ngày thực cho từng kỳ; số liệu lấy từ nhật ký theo khoảng ngày và mã giai đoạn. Sáu kỳ đầu theo lộ trình tham chiếu; sáu kỳ tiếp theo dành cho trường hợp cần theo dõi bổ sung.
A6: Kỳ | B6: Giai đoạn | C6: Từ ngày | D6: Đến ngày | E6: Ngày hợp lệ | F6: Chi quảng cáo | G6: Thuế/phí | H6: Tổng gồm thuế/phí | I6: Dự phòng còn giữ | J6: Nhóm đã tiếp cận | K6: Mức độ quan tâm thực tế | L6: Nội dung rút ra | M6: Đề xuất kỳ tiếp theo | N6: Cơ sở quyết định / bằng chứng | O6: Kiểm tra kỳ báo cáo
A7: KY01 | B7: G1 | C7: [Chưa chốt] | D7: [Chưa chốt] | E7: =IF(AND(ISNUMBER(C7),ISNUMBER(D7),D7>=C7,B7<>""),SUMIFS('03_Chi_tieu'!$S$7:$S$96,'03_Chi_tieu'!$A$7:$A$96,">="&C7,'03_Chi_tieu'!$A$7:$A$96,"<="&D7,'03_Chi_tieu'!$B$7:$B$96,B7),"") | F7: =IF(AND(AND(ISNUMBER(C7),ISNUMBER(D7),D7>=C7,B7<>""),COUNTIFS('03_Chi_tieu'!$A$7:$A$96,">="&C7,'03_Chi_tieu'!$A$7:$A$96,"<="&D7,'03_Chi_tieu'!$B$7:$B$96,B7,'03_Chi_tieu'!$I$7:$I$96,">0")>0),SUMIFS('03_Chi_tieu'!$I$7:$I$96,'03_Chi_tieu'!$A$7:$A$96,">="&C7,'03_Chi_tieu'!$A$7:$A$96,"<="&D7,'03_Chi_tieu'!$B$7:$B$96,B7),"") | G7: =IF(OR(NOT(ISNUMBER(F7)),COUNTIFS('03_Chi_tieu'!$A$7:$A$96,">="&C7,'03_Chi_tieu'!$A$7:$A$96,"<="&D7,'03_Chi_tieu'!$B$7:$B$96,B7,'03_Chi_tieu'!$I$7:$I$96,">0",'03_Chi_tieu'!$M$7:$M$96,"")>0),"",SUMIFS('03_Chi_tieu'!$M$7:$M$96,'03_Chi_tieu'!$A$7:$A$96,">="&C7,'03_Chi_tieu'!$A$7:$A$96,"<="&D7,'03_Chi_tieu'!$B$7:$B$96,B7)) | H7: =IF(AND(ISNUMBER(F7),ISNUMBER(G7)),F7+G7,"") | I7: =IF(OR(NOT(ISNUMBER(F7)),COUNTIFS('03_Chi_tieu'!$A$7:$A$96,">="&C7,'03_Chi_tieu'!$A$7:$A$96,"<="&D7,'03_Chi_tieu'!$B$7:$B$96,B7,'03_Chi_tieu'!$C$7:$C$96,"Hợp lệ",'03_Chi_tieu'!$J$7:$J$96,"")>0,AND(B7="G4",NOT(ISNUMBER('01_Thiet_lap'!$D$24)))),"",SUMIFS('03_Chi_tieu'!$K$7:$K$96,'03_Chi_tieu'!$A$7:$A$96,">="&C7,'03_Chi_tieu'!$A$7:$A$96,"<="&D7,'03_Chi_tieu'!$B$7:$B$96,B7)) | M7: Chờ đánh giá | O7: =IF(NOT(AND(ISNUMBER(C7),ISNUMBER(D7))),"Chờ chốt ngày",IF(D7<C7,"Cần rà soát khoảng ngày",IF(B7="","Cần chọn giai đoạn",IF(COUNTIFS($B$7:$B$18,B7,$C$7:$C$18,"<="&D7,$D$7:$D$18,">="&C7)>1,"Cần rà soát kỳ chồng lấn",IF(NOT(ISNUMBER(F7)),"Chưa có chi ghi nhận trong kỳ",IF(COUNTIFS('03_Chi_tieu'!$A$7:$A$96,">="&C7,'03_Chi_tieu'!$A$7:$A$96,"<="&D7,'03_Chi_tieu'!$B$7:$B$96,B7,'03_Chi_tieu'!$P$7:$P$96,"?*",'03_Chi_tieu'!$P$7:$P$96,"<>Đã ghi nhận")>0,"Có dòng chi cần rà soát","Đã tổng hợp"))))))
A8: KY02 | B8: G2 | C8: [Chưa chốt] | D8: [Chưa chốt] | E8: =IF(AND(ISNUMBER(C8),ISNUMBER(D8),D8>=C8,B8<>""),SUMIFS('03_Chi_tieu'!$S$7:$S$96,'03_Chi_tieu'!$A$7:$A$96,">="&C8,'03_Chi_tieu'!$A$7:$A$96,"<="&D8,'03_Chi_tieu'!$B$7:$B$96,B8),"") | F8: =IF(AND(AND(ISNUMBER(C8),ISNUMBER(D8),D8>=C8,B8<>""),COUNTIFS('03_Chi_tieu'!$A$7:$A$96,">="&C8,'03_Chi_tieu'!$A$7:$A$96,"<="&D8,'03_Chi_tieu'!$B$7:$B$96,B8,'03_Chi_tieu'!$I$7:$I$96,">0")>0),SUMIFS('03_Chi_tieu'!$I$7:$I$96,'03_Chi_tieu'!$A$7:$A$96,">="&C8,'03_Chi_tieu'!$A$7:$A$96,"<="&D8,'03_Chi_tieu'!$B$7:$B$96,B8),"") | G8: =IF(OR(NOT(ISNUMBER(F8)),COUNTIFS('03_Chi_tieu'!$A$7:$A$96,">="&C8,'03_Chi_tieu'!$A$7:$A$96,"<="&D8,'03_Chi_tieu'!$B$7:$B$96,B8,'03_Chi_tieu'!$I$7:$I$96,">0",'03_Chi_tieu'!$M$7:$M$96,"")>0),"",SUMIFS('03_Chi_tieu'!$M$7:$M$96,'03_Chi_tieu'!$A$7:$A$96,">="&C8,'03_Chi_tieu'!$A$7:$A$96,"<="&D8,'03_Chi_tieu'!$B$7:$B$96,B8)) | H8: =IF(AND(ISNUMBER(F8),ISNUMBER(G8)),F8+G8,"") | I8: =IF(OR(NOT(ISNUMBER(F8)),COUNTIFS('03_Chi_tieu'!$A$7:$A$96,">="&C8,'03_Chi_tieu'!$A$7:$A$96,"<="&D8,'03_Chi_tieu'!$B$7:$B$96,B8,'03_Chi_tieu'!$C$7:$C$96,"Hợp lệ",'03_Chi_tieu'!$J$7:$J$96,"")>0,AND(B8="G4",NOT(ISNUMBER('01_Thiet_lap'!$D$24)))),"",SUMIFS('03_Chi_tieu'!$K$7:$K$96,'03_Chi_tieu'!$A$7:$A$96,">="&C8,'03_Chi_tieu'!$A$7:$A$96,"<="&D8,'03_Chi_tieu'!$B$7:$B$96,B8)) | M8: Chờ đánh giá | O8: =IF(NOT(AND(ISNUMBER(C8),ISNUMBER(D8))),"Chờ chốt ngày",IF(D8<C8,"Cần rà soát khoảng ngày",IF(B8="","Cần chọn giai đoạn",IF(COUNTIFS($B$7:$B$18,B8,$C$7:$C$18,"<="&D8,$D$7:$D$18,">="&C8)>1,"Cần rà soát kỳ chồng lấn",IF(NOT(ISNUMBER(F8)),"Chưa có chi ghi nhận trong kỳ",IF(COUNTIFS('03_Chi_tieu'!$A$7:$A$96,">="&C8,'03_Chi_tieu'!$A$7:$A$96,"<="&D8,'03_Chi_tieu'!$B$7:$B$96,B8,'03_Chi_tieu'!$P$7:$P$96,"?*",'03_Chi_tieu'!$P$7:$P$96,"<>Đã ghi nhận")>0,"Có dòng chi cần rà soát","Đã tổng hợp"))))))
